[2022-12-16T02:24:53.747+0000] {taskinstance.py:1087} INFO - Dependencies all met for <TaskInstance: weekly_wrapped_dag.generate_wrapped manual__2022-12-16T02:24:48.948477+00:00 [queued]>
[2022-12-16T02:24:53.754+0000] {taskinstance.py:1087} INFO - Dependencies all met for <TaskInstance: weekly_wrapped_dag.generate_wrapped manual__2022-12-16T02:24:48.948477+00:00 [queued]>
[2022-12-16T02:24:53.755+0000] {taskinstance.py:1283} INFO - 
--------------------------------------------------------------------------------
[2022-12-16T02:24:53.756+0000] {taskinstance.py:1284} INFO - Starting attempt 1 of 1
[2022-12-16T02:24:53.757+0000] {taskinstance.py:1285} INFO - 
--------------------------------------------------------------------------------
[2022-12-16T02:24:53.767+0000] {taskinstance.py:1304} INFO - Executing <Task(PythonOperator): generate_wrapped> on 2022-12-16 02:24:48.948477+00:00
[2022-12-16T02:24:53.772+0000] {standard_task_runner.py:55} INFO - Started process 2793 to run task
[2022-12-16T02:24:53.775+0000] {standard_task_runner.py:82} INFO - Running: ['***', 'tasks', 'run', 'weekly_wrapped_dag', 'generate_wrapped', 'manual__2022-12-16T02:24:48.948477+00:00', '--job-id', '40', '--raw', '--subdir', 'DAGS_FOLDER/weekly_dag.py', '--cfg-path', '/tmp/tmpe9bf0568']
[2022-12-16T02:24:53.776+0000] {standard_task_runner.py:83} INFO - Job 40: Subtask generate_wrapped
[2022-12-16T02:24:53.823+0000] {task_command.py:389} INFO - Running <TaskInstance: weekly_wrapped_dag.generate_wrapped manual__2022-12-16T02:24:48.948477+00:00 [running]> on host 158c8f40aaa8
[2022-12-16T02:24:53.880+0000] {taskinstance.py:1513} INFO - Exporting the following env vars:
AIRFLOW_CTX_DAG_OWNER=***
AIRFLOW_CTX_DAG_ID=weekly_wrapped_dag
AIRFLOW_CTX_TASK_ID=generate_wrapped
AIRFLOW_CTX_EXECUTION_DATE=2022-12-16T02:24:48.948477+00:00
AIRFLOW_CTX_TRY_NUMBER=1
AIRFLOW_CTX_DAG_RUN_ID=manual__2022-12-16T02:24:48.948477+00:00
[2022-12-16T02:24:53.884+0000] {taskinstance.py:1772} ERROR - Task failed with exception
Traceback (most recent call last):
  File "/home/airflow/.local/lib/python3.7/site-packages/airflow/operators/python.py", line 175, in execute
    return_value = self.execute_callable()
  File "/home/airflow/.local/lib/python3.7/site-packages/airflow/operators/python.py", line 192, in execute_callable
    return self.python_callable(*self.op_args, **self.op_kwargs)
TypeError: generate_wrapped() missing 1 required positional argument: 'postgres_hook'
[2022-12-16T02:24:53.900+0000] {taskinstance.py:1327} INFO - Marking task as FAILED. dag_id=weekly_wrapped_dag, task_id=generate_wrapped, execution_date=20221216T022448, start_date=20221216T022453, end_date=20221216T022453
[2022-12-16T02:24:53.916+0000] {standard_task_runner.py:105} ERROR - Failed to execute job 40 for task generate_wrapped (generate_wrapped() missing 1 required positional argument: 'postgres_hook'; 2793)
[2022-12-16T02:24:53.948+0000] {local_task_job.py:159} INFO - Task exited with return code 1
[2022-12-16T02:24:53.973+0000] {taskinstance.py:2582} INFO - 0 downstream tasks scheduled from follow-on schedule check
